2021-03-02 17:43:57,678 158077 WARNING  thoth.common:344: Logging to a Sentry instance is turned off
2021-03-02 17:43:57,678 158077 INFO     thoth.common:366: Logging to rsyslog endpoint is turned off
2021-03-02 17:43:57,679 158077 INFO     thoth.adviser:200: Version: 0.21.1
2021-03-02 17:43:57,718 158077 INFO     thoth.adviser:722: Starting resolver using predictor 'RandomWalk' with random seed set to 9068, predictor parameters: {}
2021-03-02 17:43:57,738 158077 CRITICAL root:105: Traceback (most recent call last):
  File "/usr/lib/python3/dist-packages/sqlalchemy/engine/base.py", line 2276, in _wrap_pool_connect
    return fn()
  File "/usr/lib/python3/dist-packages/sqlalchemy/pool/base.py", line 363, in connect
    return _ConnectionFairy._checkout(self)
  File "/usr/lib/python3/dist-packages/sqlalchemy/pool/base.py", line 760, in _checkout
    fairy = _ConnectionRecord.checkout(pool)
  File "/usr/lib/python3/dist-packages/sqlalchemy/pool/base.py", line 492, in checkout
    rec = pool._do_get()
  File "/usr/lib/python3/dist-packages/sqlalchemy/pool/impl.py", line 139, in _do_get
    self._dec_overflow()
  File "/usr/lib/python3/dist-packages/sqlalchemy/util/langhelpers.py", line 68, in __exit__
    compat.reraise(exc_type, exc_value, exc_tb)
  File "/usr/lib/python3/dist-packages/sqlalchemy/util/compat.py", line 153, in reraise
    raise value
  File "/usr/lib/python3/dist-packages/sqlalchemy/pool/impl.py", line 136, in _do_get
    return self._create_connection()
  File "/usr/lib/python3/dist-packages/sqlalchemy/pool/base.py", line 308, in _create_connection
    return _ConnectionRecord(self)
  File "/usr/lib/python3/dist-packages/sqlalchemy/pool/base.py", line 437, in __init__
    self.__connect(first_connect_check=True)
  File "/usr/lib/python3/dist-packages/sqlalchemy/pool/base.py", line 639, in __connect
    connection = pool._invoke_creator(self)
  File "/usr/lib/python3/dist-packages/sqlalchemy/engine/strategies.py", line 114, in connect
    return dialect.connect(*cargs, **cparams)
  File "/usr/lib/python3/dist-packages/sqlalchemy/engine/default.py", line 482, in connect
    return self.dbapi.connect(*cargs, **cparams)
  File "/home/tjanicek/.local/lib/python3.8/site-packages/psycopg2/__init__.py", line 127, in connect
    conn = _connect(dsn, connection_factory=connection_factory, **kwasync)
psycopg2.OperationalError: FATAL:  password authentication failed for user "postgres"
FATAL:  password authentication failed for user "postgres"


The above exception was the direct cause of the following exception:

Traceback (most recent call last):
  File "/home/tjanicek/.local/bin/thoth-adviser", line 8, in <module>
    sys.exit(cli())
  File "/usr/lib/python3/dist-packages/click/core.py", line 764, in __call__
    return self.main(*args, **kwargs)
  File "/usr/lib/python3/dist-packages/click/core.py", line 717, in main
    rv = self.invoke(ctx)
  File "/usr/lib/python3/dist-packages/click/core.py", line 1137, in invoke
    return _process_result(sub_ctx.command.invoke(sub_ctx))
  File "/usr/lib/python3/dist-packages/click/core.py", line 956, in invoke
    return ctx.invoke(self.callback, **ctx.params)
  File "/usr/lib/python3/dist-packages/click/core.py", line 555, in invoke
    return callback(*args, **kwargs)
  File "/usr/lib/python3/dist-packages/click/decorators.py", line 17, in new_func
    return f(get_current_context(), *args, **kwargs)
  File "/home/tjanicek/.local/lib/python3.8/site-packages/thoth/adviser/cli.py", line 731, in dependency_monkey
    resolver = Resolver.get_dependency_monkey_instance(
  File "/home/tjanicek/.local/lib/python3.8/site-packages/thoth/adviser/resolver.py", line 1440, in get_dependency_monkey_instance
    graph.connect()
  File "/home/tjanicek/.local/lib/python3.8/site-packages/thoth/storages/graph/postgres.py", line 299, in connect
    if not database_exists(self._engine.url):
  File "/home/tjanicek/.local/lib/python3.8/site-packages/thoth/storages/graph/postgres_utils.py", line 84, in database_exists
    return bool(get_scalar_result(engine, text))
  File "/home/tjanicek/.local/lib/python3.8/site-packages/thoth/storages/graph/postgres_utils.py", line 72, in get_scalar_result
    result_proxy = engine.execute(sql)
  File "/usr/lib/python3/dist-packages/sqlalchemy/engine/base.py", line 2181, in execute
    connection = self._contextual_connect(close_with_result=True)
  File "/usr/lib/python3/dist-packages/sqlalchemy/engine/base.py", line 2242, in _contextual_connect
    self._wrap_pool_connect(self.pool.connect, None),
  File "/usr/lib/python3/dist-packages/sqlalchemy/engine/base.py", line 2279, in _wrap_pool_connect
    Connection._handle_dbapi_exception_noconnection(
  File "/usr/lib/python3/dist-packages/sqlalchemy/engine/base.py", line 1547, in _handle_dbapi_exception_noconnection
    util.raise_from_cause(sqlalchemy_exception, exc_info)
  File "/usr/lib/python3/dist-packages/sqlalchemy/util/compat.py", line 398, in raise_from_cause
    reraise(type(exception), exception, tb=exc_tb, cause=cause)
  File "/usr/lib/python3/dist-packages/sqlalchemy/util/compat.py", line 152, in reraise
    raise value.with_traceback(tb)
  File "/usr/lib/python3/dist-packages/sqlalchemy/engine/base.py", line 2276, in _wrap_pool_connect
    return fn()
  File "/usr/lib/python3/dist-packages/sqlalchemy/pool/base.py", line 363, in connect
    return _ConnectionFairy._checkout(self)
  File "/usr/lib/python3/dist-packages/sqlalchemy/pool/base.py", line 760, in _checkout
    fairy = _ConnectionRecord.checkout(pool)
  File "/usr/lib/python3/dist-packages/sqlalchemy/pool/base.py", line 492, in checkout
    rec = pool._do_get()
  File "/usr/lib/python3/dist-packages/sqlalchemy/pool/impl.py", line 139, in _do_get
    self._dec_overflow()
  File "/usr/lib/python3/dist-packages/sqlalchemy/util/langhelpers.py", line 68, in __exit__
    compat.reraise(exc_type, exc_value, exc_tb)
  File "/usr/lib/python3/dist-packages/sqlalchemy/util/compat.py", line 153, in reraise
    raise value
  File "/usr/lib/python3/dist-packages/sqlalchemy/pool/impl.py", line 136, in _do_get
    return self._create_connection()
  File "/usr/lib/python3/dist-packages/sqlalchemy/pool/base.py", line 308, in _create_connection
    return _ConnectionRecord(self)
  File "/usr/lib/python3/dist-packages/sqlalchemy/pool/base.py", line 437, in __init__
    self.__connect(first_connect_check=True)
  File "/usr/lib/python3/dist-packages/sqlalchemy/pool/base.py", line 639, in __connect
    connection = pool._invoke_creator(self)
  File "/usr/lib/python3/dist-packages/sqlalchemy/engine/strategies.py", line 114, in connect
    return dialect.connect(*cargs, **cparams)
  File "/usr/lib/python3/dist-packages/sqlalchemy/engine/default.py", line 482, in connect
    return self.dbapi.connect(*cargs, **cparams)
  File "/home/tjanicek/.local/lib/python3.8/site-packages/psycopg2/__init__.py", line 127, in connect
    conn = _connect(dsn, connection_factory=connection_factory, **kwasync)
sqlalchemy.exc.OperationalError: (psycopg2.OperationalError) FATAL:  password authentication failed for user "postgres"
FATAL:  password authentication failed for user "postgres"

(Background on this error at: http://sqlalche.me/e/e3q8)
